<?xml version="1.0" encoding="UTF-8"?>
<!-- Generated by org.testng.reporters.JUnitReportReporter -->
<testsuite skipped="5" hostname="DESKTOP-14JT5SD" name="org.retryanalyzer.Student1" tests="9" failures="1" timestamp="21 Feb 2021 07:21:07 GMT" time="0.019" errors="0">
  <testcase name="tc04" time="0.000" classname="org.retryanalyzer.Student1"/>
  <testcase name="tc03" time="0.000" classname="org.retryanalyzer.Student1"/>
  <testcase name="tc02" time="0.000" classname="org.retryanalyzer.Student1">
    <failure type="java.lang.AssertionError" message="expected [true] but found [false]">
      <![CDATA[java.lang.AssertionError: expected [true] but found [false]
at org.testng.Assert.fail(Assert.java:96)
at org.testng.Assert.failNotEquals(Assert.java:776)
at org.testng.Assert.assertTrue(Assert.java:44)
at org.testng.Assert.assertTrue(Assert.java:54)
at org.retryanalyzer.Student1.tc02(Student1.java:14)
at sun.reflect.NativeMethodAccessorImpl.invoke0(Native Method)
at sun.reflect.NativeMethodAccessorImpl.invoke(Unknown Source)
at sun.reflect.DelegatingMethodAccessorImpl.invoke(Unknown Source)
at java.lang.reflect.Method.invoke(Unknown Source)
at org.testng.internal.MethodInvocationHelper.invokeMethod(MethodInvocationHelper.java:124)
at org.testng.internal.Invoker.invokeMethod(Invoker.java:583)
at org.testng.internal.Invoker.retryFailed(Invoker.java:839)
at org.testng.internal.Invoker.invokeTestMethods(Invoker.java:1010)
at org.testng.internal.TestMethodWorker.invokeTestMethods(TestMethodWorker.java:125)
at org.testng.internal.TestMethodWorker.run(TestMethodWorker.java:109)
at org.testng.TestRunner.privateRun(TestRunner.java:648)
at org.testng.TestRunner.run(TestRunner.java:505)
at org.testng.SuiteRunner.runTest(SuiteRunner.java:455)
at org.testng.SuiteRunner.runSequentially(SuiteRunner.java:450)
at org.testng.SuiteRunner.privateRun(SuiteRunner.java:415)
at org.testng.SuiteRunner.run(SuiteRunner.java:364)
at org.testng.SuiteRunnerWorker.runSuite(SuiteRunnerWorker.java:52)
at org.testng.SuiteRunnerWorker.run(SuiteRunnerWorker.java:84)
at org.testng.TestNG.runSuitesSequentially(TestNG.java:1208)
at org.testng.TestNG.runSuitesLocally(TestNG.java:1137)
at org.testng.TestNG.runSuites(TestNG.java:1049)
at org.testng.TestNG.run(TestNG.java:1017)
at org.testng.remote.AbstractRemoteTestNG.run(AbstractRemoteTestNG.java:132)
at org.testng.remote.RemoteTestNG.initAndRun(RemoteTestNG.java:230)
at org.testng.remote.RemoteTestNG.main(RemoteTestNG.java:76)
]]>
    </failure>
  </testcase> <!-- tc02 -->
  <testcase name="tc02" time="0.000" classname="org.retryanalyzer.Student1">
    <skipped/>
  </testcase> <!-- tc02 -->
  <testcase name="tc01" time="0.013" classname="org.retryanalyzer.Student1"/>
  <testcase name="tc02" time="0.002" classname="org.retryanalyzer.Student1">
    <skipped/>
  </testcase> <!-- tc02 -->
  <testcase name="tc02" time="0.001" classname="org.retryanalyzer.Student1">
    <skipped/>
  </testcase> <!-- tc02 -->
  <testcase name="tc02" time="0.001" classname="org.retryanalyzer.Student1">
    <skipped/>
  </testcase> <!-- tc02 -->
  <testcase name="tc02" time="0.002" classname="org.retryanalyzer.Student1">
    <skipped/>
  </testcase> <!-- tc02 -->
</testsuite> <!-- org.retryanalyzer.Student1 -->
